Workbook

Sheet Price Data
A1: Date | B1: Open | C1: High | D1: Low | E1: Close | F1: Adj Close | G1: Volume | L1: Date | M1: Open | N1: High | O1: Low | P1: Close | Q1: Adj Close | R1: Volume | X1: Date | Y1: Open | Z1: High | AA1: Low | AB1: Close | AC1: Adj Close | AD1: Volume
A2: 46235 | B2: 384.35 | C2: 397.25 | D2: 367.5 | E2: 384.7 | F2: 384.7 | G2: 5919747 | X2: 46235 | Y2: 1.1538 | Z2: 1.1712 | AA2: 1.1503 | AB2: 1.1589 | AC2: 1.1589 | AD2: -
A3: 46204 | B3: 383.35 | C3: 401 | D3: 366.1 | E3: 386.95 | F3: 386.95 | G3: 7561757 | L3: 46235 | M3: 197.69 | N3: 230.47 | O3: 196.85 | P3: 220.78 | Q3: 220.53 | R3: 2682633400 | X3: 46204 | Y3: 1.1413 | Z3: 1.1535 | AA3: 1.1354 | AB3: 1.1524 | AC3: 1.1524 | AD3: -
A4: 46174 | B4: 381.95 | C4: 397.05 | D4: 369.35 | E4: 383.65 | F4: 383.65 | G4: 10206822 | L4: 46204 | M4: 196.2 | N4: 214.39 | O4: 190.01 | P4: 200.75 | Q4: 200.53 | R4: 2852595400 | X4: 46174 | Y4: 1.1648 | Z4: 1.1667 | AA4: 1.1325 | AB4: 1.1422 | AC4: 1.1422 | AD4: -
A5: 46143 | B5: 364.65 | C5: 394.5 | D5: 350.5 | E5: 382.55 | F5: 382.55 | G5: 8917728 | L5: 46177 | M5: 0.25 Dividend | X5: 46143 | Y5: 1.173 | Z5: 1.1797 | AA5: 1.1577 | AB5: 1.166 | AC5: 1.166 | AD5: -
A6: 46141 | B6: 7.2 Dividend | L6: 46174 | M6: 215.73 | N6: 232.28 | O6: 189.8 | P6: 200.09 | Q6: 199.87 | R6: 3424306300 | X6: 46113 | Y6: 1.1571 | Z6: 1.1851 | AA6: 1.1507 | AB6: 1.1685 | AC6: 1.1685 | AD6: -
A7: 46113 | B7: 355.1 | C7: 380.8 | D7: 343.65 | E7: 366.05 | F7: 366.05 | G7: 9941433 | L7: 46143 | M7: 201.28 | N7: 236.54 | O7: 194.74 | P7: 211.14 | Q7: 210.66 | R7: 3324840700 | X7: 46082 | Y7: 1.1819 | Z7: 1.1819 | AA7: 1.1416 | AB7: 1.146 | AC7: 1.146 | AD7: -
A8: 46082 | B8: 388.1 | C8: 389.7 | D8: 338.85 | E8: 349.35 | F8: 342.62 | G8: 11076868 | L8: 46113 | M8: 176 | N8: 216.83 | O8: 171.37 | P8: 199.57 | Q8: 199.11 | R8: 3129548700 | X8: 46054 | Y8: 1.1855 | Z8: 1.1928 | AA8: 1.1743 | AB8: 1.1803 | AC8: 1.1803 | AD8: -
A9: 46054 | B9: 389.75 | C9: 405.8 | D9: 364 | E9: 397.4 | F9: 389.74 | G9: 6921357 | L9: 46092 | M9: 0.01 Dividend | X9: 46023 | Y9: 1.1751 | Z9: 1.2024 | AA9: 1.1585 | AB9: 1.1855 | AC9: 1.1855 | AD9: -
A10: 46023 | B10: 365.95 | C10: 396.9 | D10: 355.65 | E10: 387 | F10: 379.54 | G10: 6537388 | L10: 46082 | M10: 175.01 | N10: 188.88 | O10: 164.27 | P10: 174.4 | Q10: 174 | R10: 4027150800 | X10: 45992 | Y10: 1.1602 | Z10: 1.1809 | AA10: 1.159 | AB10: 1.1747 | AC10: 1.1747 | AD10: -
A11: 45992 | B11: 373.55 | C11: 381.65 | D11: 360.8 | E11: 366.6 | F11: 359.54 | G11: 6068941 | L11: 46054 | M11: 187.2 | N11: 197.63 | O11: 171.03 | P11: 177.19 | Q11: 176.78 | R11: 3745445000 | X11: 45962 | Y11: 1.1601 | Z11: 1.1654 | AA11: 1.147 | AB11: 1.1597 | AC11: 1.1597 | AD11: -
A12: 45962 | B12: 363.1 | C12: 377.25 | D12: 349.05 | E12: 375.6 | F12: 368.36 | G12: 5941387 | L12: 46023 | M12: 189.84 | N12: 194.49 | O12: 177.61 | P12: 191.13 | Q12: 190.68 | R12: 3292228600 | X12: 45931 | Y12: 1.1736 | Z12: 1.1779 | AA12: 1.1524 | AB12: 1.1572 | AC12: 1.1572 | AD12: -
A13: 45931 | B13: 367.8 | C13: 398 | D13: 360.55 | E13: 362.65 | F13: 355.66 | G13: 7278137 | L13: 45995 | M13: 0.01 Dividend | X13: 45901 | Y13: 1.1692 | Z13: 1.1873 | AA13: 1.161 | AB13: 1.1731 | AC13: 1.1731 | AD13: -
A14: 45901 | B14: 399.5 | C14: 407.85 | D14: 360.25 | E14: 368.5 | F14: 361.4 | G14: 7992831 | L14: 45992 | M14: 174.76 | N14: 192.69 | O14: 170.31 | P14: 186.5 | Q14: 186.06 | R14: 3629693700 | X14: 45870 | Y14: 1.1424 | Z14: 1.1731 | AA14: 1.1395 | AB14: 1.1686 | AC14: 1.1686 | AD14: -
A15: 45870 | B15: 387.3 | C15: 408.35 | D15: 369.15 | E15: 397.9 | F15: 390.23 | G15: 4892388 | L15: 45962 | M15: 208.08 | N15: 211.34 | O15: 169.55 | P15: 177 | Q15: 176.58 | R15: 4160148300 | X15: 45839 | Y15: 1.1787 | Z15: 1.183 | AA15: 1.1407 | AB15: 1.1429 | AC15: 1.1429 | AD15: -
A16: 45839 | B16: 363.95 | C16: 399 | D16: 360.4 | E16: 389.35 | F16: 381.85 | G16: 6308286 | L16: 45931 | M16: 185.24 | N16: 212.19 | O16: 176.76 | P16: 202.49 | Q16: 202.01 | R16: 4031017400 | X16: 45809 | Y16: 1.1351 | Z16: 1.1772 | AA16: 1.1351 | AB16: 1.1727 | AC16: 1.1727 | AD16: -
A17: 45809 | B17: 368.45 | C17: 388.4 | D17: 348.35 | E17: 363.1 | F17: 356.1 | G17: 7318701 | L17: 45911 | M17: 0.01 Dividend | X17: 45778 | Y17: 1.1325 | Z17: 1.1419 | AA17: 1.1075 | AB17: 1.1351 | AC17: 1.1351 | AD17: -
A18: 45782 | B18: 7 Dividend | L18: 45901 | M18: 170 | N18: 187.35 | O18: 164.07 | P18: 186.58 | Q18: 186.13 | R18: 3890495300 | X18: 45748 | Y18: 1.0819 | Z18: 1.1547 | AA18: 1.078 | AB18: 1.1389 | AC18: 1.1389 | AD18: -
A19: 45778 | B19: 390.85 | C19: 394.67 | D19: 364.85 | E19: 372.4 | F19: 365.23 | G19: 7629107 | L19: 45870 | M19: 174.09 | N19: 184.48 | O19: 168.8 | P19: 174.18 | Q19: 173.75 | R19: 3608891200 | X19: 45717 | Y19: 1.0381 | Z19: 1.0954 | AA19: 1.0381 | AB19: 1.0824 | AC19: 1.0824 | AD19: -
A20: 45748 | B20: 346.95 | C20: 389.8 | D20: 326.65 | E20: 387 | F20: 372.79 | G20: 12424842 | L20: 45839 | M20: 156.29 | N20: 183.3 | O20: 151.49 | P20: 177.87 | Q20: 177.43 | R20: 3596804400 | X20: 45689 | Y20: 1.0364 | Z20: 1.0529 | AA20: 1.0213 | AB20: 1.0395 | AC20: 1.0395 | AD20: -
A21: 45717 | B21: 351.05 | C21: 370.8 | D21: 337.7 | E21: 342.85 | F21: 330.26 | G21: 10734047 | L21: 45819 | M21: 0.01 Dividend | X21: 45658 | Y21: 1.0352 | Z21: 1.0534 | AA21: 1.0184 | AB21: 1.0397 | AC21: 1.0397 | AD21: -
A22: 45689 | B22: 349.65 | C22: 355.15 | D22: 332.05 | E22: 353 | F22: 340.04 | G22: 9440096 | L22: 45809 | M22: 135.49 | N22: 158.71 | O22: 135.4 | P22: 157.99 | Q22: 157.6 | R22: 3821296800 | X22: 45627 | Y22: 1.0581 | Z22: 1.0626 | AA22: 1.0344 | AB22: 1.0406 | AC22: 1.0406 | AD22: -
A23: 45658 | B23: 341.85 | C23: 368.7 | D23: 323.7 | E23: 358.5 | F23: 345.34 | G23: 9345763 | L23: 45778 | M23: 113.08 | N23: 143.49 | O23: 110.82 | P23: 135.13 | Q23: 134.79 | R23: 4756803800 | X23: 45597 | Y23: 1.0886 | Z23: 1.0933 | AA23: 1.034 | AB23: 1.0581 | AC23: 1.0581 | AD23: -
A24: 45627 | B24: 324.35 | C24: 352.65 | D24: 322.8 | E24: 341.85 | F24: 329.3 | G24: 8685718 | L24: 45748 | M24: 108.52 | N24: 115.1 | O24: 86.62 | P24: 108.92 | Q24: 108.65 | R24: 6811006400 | X24: 45566 | Y24: 1.1137 | Z24: 1.1146 | AA24: 1.0763 | AB24: 1.0859 | AC24: 1.0859 | AD24: -
A25: 45597 | B25: 342.15 | C25: 353.45 | D25: 316.3 | E25: 328.65 | F25: 316.58 | G25: 8734153 | L25: 45728 | M25: 0.01 Dividend | X25: 45536 | Y25: 1.1062 | Z25: 1.1212 | AA25: 1.1003 | AB25: 1.117 | AC25: 1.117 | AD25: -
A26: 45566 | B26: 399.85 | C26: 400.5 | D26: 337.15 | E26: 344.25 | F26: 331.61 | G26: 9032229 | L26: 45717 | M26: 123.51 | N26: 123.7 | O26: 103.65 | P26: 108.38 | Q26: 108.11 | R26: 6177950300 | X26: 45505 | Y26: 1.0824 | Z26: 1.121 | AA26: 1.0778 | AB26: 1.1062 | AC26: 1.1062 | AD26: -
A27: 45536 | B27: 396.2 | C27: 413.2 | D27: 364.55 | E27: 402.05 | F27: 387.29 | G27: 9043102 | L27: 45689 | M27: 114.75 | N27: 143.44 | O27: 113.01 | P27: 124.92 | Q27: 124.59 | R27: 4755230400 | X27: 45474 | Y27: 1.0735 | Z27: 1.0947 | AA27: 1.0711 | AB27: 1.0816 | AC27: 1.0816 | AD27: -
A28: 45505 | B28: 394.25 | C28: 400.65 | D28: 374 | E28: 396.6 | F28: 382.04 | G28: 7391506 | L28: 45658 | M28: 136 | N28: 153.13 | O28: 116.25 | P28: 120.07 | Q28: 119.76 | R28: 5948400800 | X28: 45444 | Y28: 1.0858 | Z28: 1.0918 | AA28: 1.0668 | AB28: 1.0722 | AC28: 1.0722 | AD28: -
A29: 45474 | B29: 414.4 | C29: 416.95 | D29: 387.1 | E29: 400.65 | F29: 385.94 | G29: 7117521 | L29: 45631 | M29: 0.01 Dividend | X29: 45413 | Y29: 1.0667 | Z29: 1.0897 | AA29: 1.065 | AB29: 1.0835 | AC29: 1.0835 | AD29: -
A30: 45444 | B30: 452.65 | C30: 461.85 | D30: 407.05 | E30: 410.05 | F30: 394.99 | G30: 5947219 | L30: 45627 | M30: 138.83 | N30: 146.54 | O30: 126.86 | P30: 134.29 | Q30: 133.94 | R30: 4085855200 | X30: 45383 | Y30: 1.0793 | Z30: 1.0889 | AA30: 1.0604 | AB30: 1.0716 | AC30: 1.0716 | AD30: -
A31: 45413 | B31: 436 | C31: 458.4 | D31: 432.9 | E31: 452.1 | F31: 435.5 | G31: 5783579 | L31: 45597 | M31: 134.7 | N31: 152.89 | O31: 131.8 | P31: 138.25 | Q31: 137.88 | R31: 4497414600 | X31: 45352 | Y31: 1.0805 | Z31: 1.0978 | AA31: 1.0769 | AB31: 1.0801 | AC31: 1.0801 | AD31: -
A32: 45408 | B32: 6.6 Dividend | L32: 45566 | M32: 121.77 | N32: 144.42 | O32: 115.14 | P32: 132.76 | Q32: 132.4 | R32: 5627917200 | X32: 45323 | Y32: 1.0804 | Z32: 1.0898 | AA32: 1.0696 | AB32: 1.0839 | AC32: 1.0839 | AD32: -
A33: 45383 | B33: 437.8 | C33: 449.05 | D33: 407.85 | E33: 439.65 | F33: 423.51 | G33: 6906794 | L33: 45547 | M33: 0.01 Dividend | X33: 45292 | Y33: 1.1056 | Z33: 1.1053 | AA33: 1.0797 | AB33: 1.0843 | AC33: 1.0843 | AD33: -
A34: 45352 | B34: 442.8 | C34: 457.5 | D34: 428.1 | E34: 438.65 | F34: 416.14 | G34: 5355411 | L34: 45536 | M34: 116.01 | N34: 127.67 | O34: 100.95 | P34: 121.44 | Q34: 121.12 | R34: 6271163200 | X34: 45261 | Y34: 1.0892 | Z34: 1.1139 | AA34: 0.9191 | AB34: 1.1056 | AC34: 1.1056 | AD34: -
A35: 45323 | B35: 447.45 | C35: 460.6 | D35: 417.1 | E35: 441.7 | F35: 419.04 | G35: 6364642 | L35: 45505 | M35: 117.53 | N35: 131.26 | O35: 90.69 | P35: 119.37 | Q35: 119.04 | R35: 8105367800 | X35: 45231 | Y35: 1.0579 | Z35: 1.1017 | AA35: 1.0523 | AB35: 1.0974 | AC35: 1.0974 | AD35: -
A36: 45292 | B36: 450.65 | C36: 454.05 | D36: 417 | E36: 444.7 | F36: 421.88 | G36: 5599193 | L36: 45474 | M36: 123.47 | N36: 136.15 | O36: 102.54 | P36: 117.02 | Q36: 116.7 | R36: 6405438600 | X36: 45200 | Y36: 1.0588 | Z36: 1.069 | AA36: 1.045 | AB36: 1.0615 | AC36: 1.0615 | AD36: -
A37: 45261 | B37: 434.4 | C37: 460 | D37: 433.65 | E37: 450.65 | F37: 427.53 | G37: 5010760 | L37: 45454 | M37: 0.01 Dividend | X37: 45170 | Y37: 1.0844 | Z37: 1.0881 | AA37: 1.0492 | AB37: 1.0588 | AC37: 1.0588 | AD37: -
A38: 45231 | B38: 398.3 | C38: 435 | D38: 389.8 | E38: 431.05 | F38: 408.93 | G38: 7065162 | L38: 45444 | M38: 113.62 | N38: 140.76 | O38: 112 | P38: 123.54 | Q38: 123.2 | R38: 7424176700 | X38: 45139 | Y38: 1.0998 | Z38: 1.1058 | AA38: 1.0767 | AB38: 1.0933 | AC38: 1.0933 | AD38: -
A39: 45200 | B39: 394.75 | C39: 400.9 | D39: 372 | E39: 396.15 | F39: 375.82 | G39: 7012300 | L39: 45453 | M39: 10:1 Stock Splits | X39: 45108 | Y39: 1.0918 | Z39: 1.1276 | AA39: 1.0834 | AB39: 1.1024 | AC39: 1.1024 | AD39: -
A40: 45170 | B40: 404 | C40: 413.2 | D40: 385.65 | E40: 393.2 | F40: 373.02 | G40: 7305542 | L40: 45413 | M40: 85.08 | N40: 115.82 | O40: 81.25 | P40: 109.63 | Q40: 109.32 | R40: 9645174000 | X40: 45078 | Y40: 1.0695 | Z40: 1.1011 | AA40: 1.0664 | AB40: 1.0868 | AC40: 1.0868 | AD40: -
...

Sheet Portfolio Analysis
A1: Date | B1: L'Oreal Adj Close EUR | C1: EUR/USD Rate | D1: L'Oreal Adj Close USD | E1: NVIDIA's Adj Close USD | F1: L'Oreal Monthly Return | G1: NVIDIA Monthly Return | I1: Metric | J1: L'Oreal | K1: NVDIA
A2: 43466 | B2: =VLOOKUP(A2,'Price Data'!$A$2:$F$150,6,FALSE()) -> 186.03 | C2: =VLOOKUP(A2,'Price Data'!$X$2:$AC$150,6,FALSE()) -> 1.1488 | D2: =B2*C2 -> 213.71126 | E2: =SUMIFS('Price Data'!$Q$2:$Q$150,'Price Data'!$L$2:$L$150,A2) -> 3.56 | I2: Average Monthly Return | J2: =AVERAGE(F3:F93) -> 0.010338799 | K2: =AVERAGE(G3:G93) -> 0.054880661
A3: =EDATE(A2,1) -> 43497 | B3: =VLOOKUP(A3,'Price Data'!$A$2:$F$150,6,FALSE()) -> 196.48 | C3: =VLOOKUP(A3,'Price Data'!$X$2:$AC$150,6,FALSE()) -> 1.138 | D3: =B3*C3 -> 223.59424 | E3: =SUMIFS('Price Data'!$Q$2:$Q$150,'Price Data'!$L$2:$L$150,A3) -> 3.82 | F3: =(D3-D2)/D2 -> 0.046244526 | G3: =(E3-E2)/E2 -> 0.073033708 | I3: Monthly Volatility | J3: =_xlfn.STDEV.S(F3:F93) -> 0.067241567 | K3: =_xlfn.STDEV.S(G3:G93) -> 0.13236573
A4: =EDATE(A3,1) -> 43525 | B4: =VLOOKUP(A4,'Price Data'!$A$2:$F$150,6,FALSE()) -> 212.33 | C4: =VLOOKUP(A4,'Price Data'!$X$2:$AC$150,6,FALSE()) -> 1.1233 | D4: =B4*C4 -> 238.51029 | E4: =SUMIFS('Price Data'!$Q$2:$Q$150,'Price Data'!$L$2:$L$150,A4) -> 4.45 | F4: =(D4-D3)/D3 -> 0.066710345 | G4: =(E4-E3)/E3 -> 0.16492147 | I4: Correlation | J4: =CORREL(F3:F93,G3:G93) -> 0.283103
A5: =EDATE(A4,1) -> 43556 | B5: =VLOOKUP(A5,'Price Data'!$A$2:$F$150,6,FALSE()) -> 220.51 | C5: =VLOOKUP(A5,'Price Data'!$X$2:$AC$150,6,FALSE()) -> 1.1185 | D5: =B5*C5 -> 246.64043 | E5: =SUMIFS('Price Data'!$Q$2:$Q$150,'Price Data'!$L$2:$L$150,A5) -> 4.48 | F5: =(D5-D4)/D4 -> 0.034087192 | G5: =(E5-E4)/E4 -> 0.006741573 | I5: Monthly risk-free rate | J5: 0.003
A6: =EDATE(A5,1) -> 43586 | B6: =VLOOKUP(A6,'Price Data'!$A$2:$F$150,6,FALSE()) -> 216.28 | C6: =VLOOKUP(A6,'Price Data'!$X$2:$AC$150,6,FALSE()) -> 1.1131 | D6: =B6*C6 -> 240.74127 | E6: =SUMIFS('Price Data'!$Q$2:$Q$150,'Price Data'!$L$2:$L$150,A6) -> 3.36 | F6: =(D6-D5)/D5 -> -0.023918085 | G6: =(E6-E5)/E5 -> -0.25
A7: =EDATE(A6,1) -> 43617 | B7: =VLOOKUP(A7,'Price Data'!$A$2:$F$150,6,FALSE()) -> 225.36 | C7: =VLOOKUP(A7,'Price Data'!$X$2:$AC$150,6,FALSE()) -> 1.1391 | D7: =B7*C7 -> 256.70758 | E7: =SUMIFS('Price Data'!$Q$2:$Q$150,'Price Data'!$L$2:$L$150,A7) -> 4.07 | F7: =(D7-D6)/D6 -> 0.066321442 | G7: =(E7-E6)/E6 -> 0.21130952
A8: =EDATE(A7,1) -> 43647 | B8: =VLOOKUP(A8,'Price Data'!$A$2:$F$150,6,FALSE()) -> 217.72 | C8: =VLOOKUP(A8,'Price Data'!$X$2:$AC$150,6,FALSE()) -> 1.1158 | D8: =B8*C8 -> 242.93198 | E8: =SUMIFS('Price Data'!$Q$2:$Q$150,'Price Data'!$L$2:$L$150,A8) -> 4.18 | F8: =(D8-D7)/D7 -> -0.053662616 | G8: =(E8-E7)/E7 -> 0.027027027 | I8: L'Oreal Weight | J8: NVIDIA Weight | K8: Expected Return | L8: Variance | M8: Volatility | N8: Sharpe Ratio
A9: =EDATE(A8,1) -> 43678 | B9: =VLOOKUP(A9,'Price Data'!$A$2:$F$150,6,FALSE()) -> 223.65 | C9: =VLOOKUP(A9,'Price Data'!$X$2:$AC$150,6,FALSE()) -> 1.1012 | D9: =B9*C9 -> 246.28338 | E9: =SUMIFS('Price Data'!$Q$2:$Q$150,'Price Data'!$L$2:$L$150,A9) -> 4.16 | F9: =(D9-D8)/D8 -> 0.013795648 | G9: =(E9-E8)/E8 -> -0.004784689 | I9: 0 | J9: =1-I9 -> 1 | K9: =I9*$J$2+J9*$K$2 -> 0.054880661 | L9: =I9^2*$J$3^2+J9^2*$K$3^2+2*I9*J9*$J$3*$K$3*$J$4 -> 0.017520687 | M9: =SQRT(L9) -> 0.13236573 | N9: =(K9-$J$5)/M9 -> 0.39194934
A10: =EDATE(A9,1) -> 43709 | B10: =VLOOKUP(A10,'Price Data'!$A$2:$F$150,6,FALSE()) -> 231.12 | C10: =VLOOKUP(A10,'Price Data'!$X$2:$AC$150,6,FALSE()) -> 1.0943 | D10: =B10*C10 -> 252.91462 | E10: =SUMIFS('Price Data'!$Q$2:$Q$150,'Price Data'!$L$2:$L$150,A10) -> 4.32 | F10: =(D10-D9)/D9 -> 0.026925227 | G10: =(E10-E9)/E9 -> 0.038461538 | I10: =I9+5% -> 0.05 | J10: =1-I10 -> 0.95 | K10: =I10*$J$2+J10*$K$2 -> 0.052653568 | L10: =I10^2*$J$3^2+J10^2*$K$3^2+2*I10*J10*$J$3*$K$3*$J$4 -> 0.0160631 | M10: =SQRT(L10) -> 0.12674028 | N10: =(K10-$J$5)/M10 -> 0.39177415
A11: =EDATE(A10,1) -> 43739 | B11: =VLOOKUP(A11,'Price Data'!$A$2:$F$150,6,FALSE()) -> 235.53 | C11: =VLOOKUP(A11,'Price Data'!$X$2:$AC$150,6,FALSE()) -> 1.1154 | D11: =B11*C11 -> 262.71016 | E11: =SUMIFS('Price Data'!$Q$2:$Q$150,'Price Data'!$L$2:$L$150,A11) -> 4.99 | F11: =(D11-D10)/D10 -> 0.038730644 | G11: =(E11-E10)/E10 -> 0.15509259 | I11: =I10+5% -> 0.1 | J11: =1-I11 -> 0.9 | K11: =I11*$J$2+J11*$K$2 -> 0.050426475 | L11: =I11^2*$J$3^2+J11^2*$K$3^2+2*I11*J11*$J$3*$K$3*$J$4 -> 0.014690526 | M11: =SQRT(L11) -> 0.12120448 | N11: =(K11-$J$5)/M11 -> 0.39129308
A12: =EDATE(A11,1) -> 43770 | B12: =VLOOKUP(A12,'Price Data'!$A$2:$F$150,6,FALSE()) -> 232.74 | C12: =VLOOKUP(A12,'Price Data'!$X$2:$AC$150,6,FALSE()) -> 1.102 | D12: =B12*C12 -> 256.47948 | E12: =SUMIFS('Price Data'!$Q$2:$Q$150,'Price Data'!$L$2:$L$150,A12) -> 5.38 | F12: =(D12-D11)/D11 -> -0.023716943 | G12: =(E12-E11)/E11 -> 0.078156313 | I12: =I11+5% -> 0.15 | J12: =1-I12 -> 0.85 | K12: =I12*$J$2+J12*$K$2 -> 0.048199382 | L12: =I12^2*$J$3^2+J12^2*$K$3^2+2*I12*J12*$J$3*$K$3*$J$4 -> 0.013402965 | M12: =SQRT(L12) -> 0.11577118 | N12: =(K12-$J$5)/M12 -> 0.39041999
A13: =EDATE(A12,1) -> 43800 | B13: =VLOOKUP(A13,'Price Data'!$A$2:$F$150,6,FALSE()) -> 237.51 | C13: =VLOOKUP(A13,'Price Data'!$X$2:$AC$150,6,FALSE()) -> 1.1202 | D13: =B13*C13 -> 266.0587 | E13: =SUMIFS('Price Data'!$Q$2:$Q$150,'Price Data'!$L$2:$L$150,A13) -> 5.84 | F13: =(D13-D12)/D12 -> 0.037348883 | G13: =(E13-E12)/E12 -> 0.085501859 | I13: =I12+5% -> 0.2 | J13: =1-I13 -> 0.8 | K13: =I13*$J$2+J13*$K$2 -> 0.045972288 | L13: =I13^2*$J$3^2+J13^2*$K$3^2+2*I13*J13*$J$3*$K$3*$J$4 -> 0.012200417 | M13: =SQRT(L13) -> 0.1104555 | N13: =(K13-$J$5)/M13 -> 0.38904617
A14: =EDATE(A13,1) -> 43831 | B14: =VLOOKUP(A14,'Price Data'!$A$2:$F$150,6,FALSE()) -> 226.62 | C14: =VLOOKUP(A14,'Price Data'!$X$2:$AC$150,6,FALSE()) -> 1.1029 | D14: =B14*C14 -> 249.9392 | E14: =SUMIFS('Price Data'!$Q$2:$Q$150,'Price Data'!$L$2:$L$150,A14) -> 5.87 | F14: =(D14-D13)/D13 -> -0.060586269 | G14: =(E14-E13)/E13 -> 0.0051369863 | I14: =I13+5% -> 0.25 | J14: =1-I14 -> 0.75 | K14: =I14*$J$2+J14*$K$2 -> 0.043745195 | L14: =I14^2*$J$3^2+J14^2*$K$3^2+2*I14*J14*$J$3*$K$3*$J$4 -> 0.011082883 | M14: =SQRT(L14) -> 0.10527527 | N14: =(K14-$J$5)/M14 -> 0.38703482
A15: =EDATE(A14,1) -> 43862 | B15: =VLOOKUP(A15,'Price Data'!$A$2:$F$150,6,FALSE()) -> 216.82 | C15: =VLOOKUP(A15,'Price Data'!$X$2:$AC$150,6,FALSE()) -> 1.103 | D15: =B15*C15 -> 239.15246 | E15: =SUMIFS('Price Data'!$Q$2:$Q$150,'Price Data'!$L$2:$L$150,A15) -> 6.71 | F15: =(D15-D14)/D14 -> -0.043157448 | G15: =(E15-E14)/E14 -> 0.14310051 | I15: =I14+5% -> 0.3 | J15: =1-I15 -> 0.7 | K15: =I15*$J$2+J15*$K$2 -> 0.041518102 | L15: =I15^2*$J$3^2+J15^2*$K$3^2+2*I15*J15*$J$3*$K$3*$J$4 -> 0.010050361 | M15: =SQRT(L15) -> 0.10025149 | N15: =(K15-$J$5)/M15 -> 0.38421477
A16: =EDATE(A15,1) -> 43891 | B16: =VLOOKUP(A16,'Price Data'!$A$2:$F$150,6,FALSE()) -> 214.93 | C16: =VLOOKUP(A16,'Price Data'!$X$2:$AC$150,6,FALSE()) -> 1.103 | D16: =B16*C16 -> 237.06779 | E16: =SUMIFS('Price Data'!$Q$2:$Q$150,'Price Data'!$L$2:$L$150,A16) -> 6.55 | F16: =(D16-D15)/D15 -> -0.008716908 | G16: =(E16-E15)/E15 -> -0.023845007 | I16: =I15+5% -> 0.35 | J16: =1-I16 -> 0.65 | K16: =I16*$J$2+J16*$K$2 -> 0.039291009 | L16: =I16^2*$J$3^2+J16^2*$K$3^2+2*I16*J16*$J$3*$K$3*$J$4 -> 0.0091028524 | M16: =SQRT(L16) -> 0.09540887 | N16: =(K16-$J$5)/M16 -> 0.38037354
A17: =EDATE(A16,1) -> 43922 | B17: =VLOOKUP(A17,'Price Data'!$A$2:$F$150,6,FALSE()) -> 238.68 | C17: =VLOOKUP(A17,'Price Data'!$X$2:$AC$150,6,FALSE()) -> 1.0877 | D17: =B17*C17 -> 259.61224 | E17: =SUMIFS('Price Data'!$Q$2:$Q$150,'Price Data'!$L$2:$L$150,A17) -> 7.26 | F17: =(D17-D16)/D16 -> 0.095097044 | G17: =(E17-E16)/E16 -> 0.10839695 | I17: =I16+5% -> 0.4 | J17: =1-I17 -> 0.6 | K17: =I17*$J$2+J17*$K$2 -> 0.037063916 | L17: =I17^2*$J$3^2+J17^2*$K$3^2+2*I17*J17*$J$3*$K$3*$J$4 -> 0.0082403569 | M17: =SQRT(L17) -> 0.090776411 | N17: =(K17-$J$5)/M17 -> 0.37525075
A18: =EDATE(A17,1) -> 43952 | B18: =VLOOKUP(A18,'Price Data'!$A$2:$F$150,6,FALSE()) -> 235.62 | C18: =VLOOKUP(A18,'Price Data'!$X$2:$AC$150,6,FALSE()) -> 1.111 | D18: =B18*C18 -> 261.77382 | E18: =SUMIFS('Price Data'!$Q$2:$Q$150,'Price Data'!$L$2:$L$150,A18) -> 8.82 | F18: =(D18-D17)/D17 -> 0.0083262023 | G18: =(E18-E17)/E17 -> 0.21487603 | I18: =I17+5% -> 0.45 | J18: =1-I18 -> 0.55 | K18: =I18*$J$2+J18*$K$2 -> 0.034836823 | L18: =I18^2*$J$3^2+J18^2*$K$3^2+2*I18*J18*$J$3*$K$3*$J$4 -> 0.0074628744 | M18: =SQRT(L18) -> 0.08638793 | N18: =(K18-$J$5)/M18 -> 0.36853324
A19: =EDATE(A18,1) -> 43983 | B19: =VLOOKUP(A19,'Price Data'!$A$2:$F$150,6,FALSE()) -> 257.03 | C19: =VLOOKUP(A19,'Price Data'!$X$2:$AC$150,6,FALSE()) -> 1.1247 | D19: =B19*C19 -> 289.08164 | E19: =SUMIFS('Price Data'!$Q$2:$Q$150,'Price Data'!$L$2:$L$150,A19) -> 9.44 | F19: =(D19-D18)/D18 -> 0.10431838 | G19: =(E19-E18)/E18 -> 0.070294785 | I19: =I18+5% -> 0.5 | J19: =1-I19 -> 0.5 | K19: =I19*$J$2+J19*$K$2 -> 0.03260973 | L19: =I19^2*$J$3^2+J19^2*$K$3^2+2*I19*J19*$J$3*$K$3*$J$4 -> 0.0067704049 | M19: =SQRT(L19) -> 0.08228247 | N19: =(K19-$J$5)/M19 -> 0.35985466
A20: =EDATE(A19,1) -> 44013 | B20: =VLOOKUP(A20,'Price Data'!$A$2:$F$150,6,FALSE()) -> 257.95 | C20: =VLOOKUP(A20,'Price Data'!$X$2:$AC$150,6,FALSE()) -> 1.1872 | D20: =B20*C20 -> 306.23824 | E20: =SUMIFS('Price Data'!$Q$2:$Q$150,'Price Data'!$L$2:$L$150,A20) -> 10.55 | F20: =(D20-D19)/D19 -> 0.059348629 | G20: =(E20-E19)/E19 -> 0.11758475 | I20: =I19+5% -> 0.55 | J20: =1-I20 -> 0.45 | K20: =I20*$J$2+J20*$K$2 -> 0.030382637 | L20: =I20^2*$J$3^2+J20^2*$K$3^2+2*I20*J20*$J$3*$K$3*$J$4 -> 0.0061629485 | M20: =SQRT(L20) -> 0.078504449 | N20: =(K20-$J$5)/M20 -> 0.34880363
A21: =EDATE(A20,1) -> 44044 | B21: =VLOOKUP(A21,'Price Data'!$A$2:$F$150,6,FALSE()) -> 252.39 | C21: =VLOOKUP(A21,'Price Data'!$X$2:$AC$150,6,FALSE()) -> 1.1918 | D21: =B21*C21 -> 300.7984 | E21: =SUMIFS('Price Data'!$Q$2:$Q$150,'Price Data'!$L$2:$L$150,A21) -> 13.3 | F21: =(D21-D20)/D20 -> -0.017763418 | G21: =(E21-E20)/E20 -> 0.26066351 | I21: =I20+5% -> 0.6 | J21: =1-I21 -> 0.4 | K21: =I21*$J$2+J21*$K$2 -> 0.028155544 | L21: =I21^2*$J$3^2+J21^2*$K$3^2+2*I21*J21*$J$3*$K$3*$J$4 -> 0.0056405052 | M21: =SQRT(L21) -> 0.075103297 | N21: =(K21-$J$5)/M21 -> 0.33494594
... A29: =EDATE(A28,1) -> 44287 | B29: =VLOOKUP(A29,'Price Data'!$A$2:$F$150,6,FALSE()) -> 315.09 | C29: =VLOOKUP(A29,'Price Data'!$X$2:$AC$150,6,FALSE()) -> 1.2127 | D29: =B29*C29 -> 382.10964 | E29: =SUMIFS('Price Data'!$Q$2:$Q$150,'Price Data'!$L$2:$L$150,A29) -> 14.94 | F29: =(D29-D28)/D28 -> 0.094171561 | G29: =(E29-E28)/E28 -> 0.125 | I29: =I28+5% -> 1 | J29: =1-I29 -> 0 | K29: =I29*$J$2+J29*$K$2 -> 0.010338799 | L29: =I29^2*$J$3^2+J29^2*$K$3^2+2*I29*J29*$J$3*$K$3*$J$4 -> 0.0045214283 | M29: =SQRT(L29) -> 0.067241567 | N29: =(K29-$J$5)/M29 -> 0.10914082
A30: =EDATE(A29,1) -> 44317 | B30: =VLOOKUP(A30,'Price Data'!$A$2:$F$150,6,FALSE()) -> 339.66 | C30: =VLOOKUP(A30,'Price Data'!$X$2:$AC$150,6,FALSE()) -> 1.219 | D30: =B30*C30 -> 414.04554 | E30: =SUMIFS('Price Data'!$Q$2:$Q$150,'Price Data'!$L$2:$L$150,A30) -> 16.17 | F30: =(D30-D29)/D29 -> 0.083577836 | G30: =(E30-E29)/E29 -> 0.082329317
A31: =EDATE(A30,1) -> 44348 | B31: =VLOOKUP(A31,'Price Data'!$A$2:$F$150,6,FALSE()) -> 346.58 | C31: =VLOOKUP(A31,'Price Data'!$X$2:$AC$150,6,FALSE()) -> 1.1902 | D31: =B31*C31 -> 412.49952 | E31: =SUMIFS('Price Data'!$Q$2:$Q$150,'Price Data'!$L$2:$L$150,A31) -> 19.91 | F31: =(D31-D30)/D30 -> -0.0037339468 | G31: =(E31-E30)/E30 -> 0.23129252
A32: =EDATE(A31,1) -> 44378 | B32: =VLOOKUP(A32,'Price Data'!$A$2:$F$150,6,FALSE()) -> 355.89 | C32: =VLOOKUP(A32,'Price Data'!$X$2:$AC$150,6,FALSE()) -> 1.1868 | D32: =B32*C32 -> 422.37025 | E32: =SUMIFS('Price Data'!$Q$2:$Q$150,'Price Data'!$L$2:$L$150,A32) -> 19.41 | F32: =(D32-D31)/D31 -> 0.023929085 | G32: =(E32-E31)/E31 -> -0.025113009 | I32: L'Oreal Weight | J32: NVIDIA Weight | K32: Expected Return | L32: Variance | M32: Volatility | N32: Sharpe Ratio
A33: =EDATE(A32,1) -> 44409 | B33: =VLOOKUP(A33,'Price Data'!$A$2:$F$150,6,FALSE()) -> 365.49 | C33: =VLOOKUP(A33,'Price Data'!$X$2:$AC$150,6,FALSE()) -> 1.1797 | D33: =B33*C33 -> 431.16855 | E33: =SUMIFS('Price Data'!$Q$2:$Q$150,'Price Data'!$L$2:$L$150,A33) -> 22.29 | F33: =(D33-D32)/D32 -> 0.020830778 | G33: =(E33-E32)/E32 -> 0.14837713 | I33: 0 | J33: =1-I33 -> 1 | K33: =I33*$J$2+J33*$K$2 -> 0.054880661 | L33: =I33^2*$J$3^2+J33^2*$K$3^2+2*I33*J33*$J$3*$K$3*$J$4 -> 0.017520687 | M33: =SQRT(L33) -> 0.13236573 | N33: =(K33-$J$5)/M33 -> 0.39194934
A34: =EDATE(A33,1) -> 44440 | B34: =VLOOKUP(A34,'Price Data'!$A$2:$F$150,6,FALSE()) -> 329.1 | C34: =VLOOKUP(A34,'Price Data'!$X$2:$AC$150,6,FALSE()) -> 1.1602 | D34: =B34*C34 -> 381.82182 | E34: =SUMIFS('Price Data'!$Q$2:$Q$150,'Price Data'!$L$2:$L$150,A34) -> 20.63 | F34: =(D34-D33)/D33 -> -0.11444882 | G34: =(E34-E33)/E33 -> -0.074472858
A35: =EDATE(A34,1) -> 44470 | B35: =VLOOKUP(A35,'Price Data'!$A$2:$F$150,6,FALSE()) -> 364.24 | C35: =VLOOKUP(A35,'Price Data'!$X$2:$AC$150,6,FALSE()) -> 1.1561 | D35: =B35*C35 -> 421.09786 | E35: =SUMIFS('Price Data'!$Q$2:$Q$150,'Price Data'!$L$2:$L$150,A35) -> 25.45 | F35: =(D35-D34)/D34 -> 0.10286485 | G35: =(E35-E34)/E34 -> 0.23364033
A36: =EDATE(A35,1) -> 44501 | B36: =VLOOKUP(A36,'Price Data'!$A$2:$F$150,6,FALSE()) -> 366.59 | C36: =VLOOKUP(A36,'Price Data'!$X$2:$AC$150,6,FALSE()) -> 1.1293 | D36: =B36*C36 -> 413.99009 | E36: =SUMIFS('Price Data'!$Q$2:$Q$150,'Price Data'!$L$2:$L$150,A36) -> 32.53 | F36: =(D36-D35)/D35 -> -0.016879157 | G36: =(E36-E35)/E35 -> 0.27819253 | I36: Goal | J36: L'Oreal Weight | K36: NVIDIA Weight
A37: =EDATE(A36,1) -> 44531 | B37: =VLOOKUP(A37,'Price Data'!$A$2:$F$150,6,FALSE()) -> 384.53 | C37: =VLOOKUP(A37,'Price Data'!$X$2:$AC$150,6,FALSE()) -> 1.1325 | D37: =B37*C37 -> 435.48023 | E37: =SUMIFS('Price Data'!$Q$2:$Q$150,'Price Data'!$L$2:$L$150,A37) -> 29.29 | F37: =(D37-D36)/D36 -> 0.051909789 | G37: =(E37-E36)/E36 -> -0.099600369 | I37: Maximum Return | J37: 0 | K37: 1
A38: =EDATE(A37,1) -> 44562 | B38: =VLOOKUP(A38,'Price Data'!$A$2:$F$150,6,FALSE()) -> 347.55 | C38: =VLOOKUP(A38,'Price Data'!$X$2:$AC$150,6,FALSE()) -> 1.1152 | D38: =B38*C38 -> 387.58776 | E38: =SUMIFS('Price Data'!$Q$2:$Q$150,'Price Data'!$L$2:$L$150,A38) -> 24.38 | F38: =(D38-D37)/D37 -> -0.10997621 | G38: =(E38-E37)/E37 -> -0.167634 | I38: Minimum Varience | J38: 0.88227243 | K38: =1-J38 -> 0.11772757
A39: =EDATE(A38,1) -> 44593 | B39: =VLOOKUP(A39,'Price Data'!$A$2:$F$150,6,FALSE()) -> 327.4 | C39: =VLOOKUP(A39,'Price Data'!$X$2:$AC$150,6,FALSE()) -> 1.1181 | D39: =B39*C39 -> 366.06594 | E39: =SUMIFS('Price Data'!$Q$2:$Q$150,'Price Data'!$L$2:$L$150,A39) -> 24.28 | F39: =(D39-D38)/D38 -> -0.055527605 | G39: =(E39-E38)/E38 -> -0.0041017227 | I39: Sharpe Ratio | J39: 0 | K39: =1-J39 -> 1
A40: =EDATE(A39,1) -> 44621 | B40: =VLOOKUP(A40,'Price Data'!$A$2:$F$150,6,FALSE()) -> 335.56 | C40: =VLOOKUP(A40,'Price Data'!$X$2:$AC$150,6,FALSE()) -> 1.1162 | D40: =B40*C40 -> 374.55207 | E40: =SUMIFS('Price Data'!$Q$2:$Q$150,'Price Data'!$L$2:$L$150,A40) -> 27.17 | F40: =(D40-D39)/D39 -> 0.023181976 | G40: =(E40-E39)/E39 -> 0.11902801
A41: =EDATE(A40,1) -> 44652 | B41: =VLOOKUP(A41,'Price Data'!$A$2:$F$150,6,FALSE()) -> 326.4 | C41: =VLOOKUP(A41,'Price Data'!$X$2:$AC$150,6,FALSE()) -> 1.0546 | D41: =B41*C41 -> 344.22144 | E41: =SUMIFS('Price Data'!$Q$2:$Q$150,'Price Data'!$L$2:$L$150,A41) -> 18.47 | F41: =(D41-D40)/D40 -> -0.080978412 | G41: =(E41-E40)/E40 -> -0.32020611
A42: =EDATE(A41,1) -> 44682 | B42: =VLOOKUP(A42,'Price Data'!$A$2:$F$150,6,FALSE()) -> 307.37 | C42: =VLOOKUP(A42,'Price Data'!$X$2:$AC$150,6,FALSE()) -> 1.0774 | D42: =B42*C42 -> 331.16044 | E42: =SUMIFS('Price Data'!$Q$2:$Q$150,'Price Data'!$L$2:$L$150,A42) -> 18.6 | F42: =(D42-D41)/D41 -> -0.037943604 | G42: =(E42-E41)/E41 -> 0.0070384407
A43: =EDATE(A42,1) -> 44713 | B43: =VLOOKUP(A43,'Price Data'!$A$2:$F$150,6,FALSE()) -> 308.07 | C43: =VLOOKUP(A43,'Price Data'!$X$2:$AC$150,6,FALSE()) -> 1.0447 | D43: =B43*C43 -> 321.84073 | E43: =SUMIFS('Price Data'!$Q$2:$Q$150,'Price Data'!$L$2:$L$150,A43) -> 15.1 | F43: =(D43-D42)/D42 -> -0.02814258 | G43: =(E43-E42)/E42 -> -0.18817204
A44: =EDATE(A43,1) -> 44743 | B44: =VLOOKUP(A44,'Price Data'!$A$2:$F$150,6,FALSE()) -> 344.37 | C44: =VLOOKUP(A44,'Price Data'!$X$2:$AC$150,6,FALSE()) -> 1.0227 | D44: =B44*C44 -> 352.1872 | E44: =SUMIFS('Price Data'!$Q$2:$Q$150,'Price Data'!$L$2:$L$150,A44) -> 18.09 | F44: =(D44-D43)/D43 -> 0.094290335 | G44: =(E44-E43)/E43 -> 0.19801325
A45: =EDATE(A44,1) -> 44774 | B45: =VLOOKUP(A45,'Price Data'!$A$2:$F$150,6,FALSE()) -> 321.12 | C45: =VLOOKUP(A45,'Price Data'!$X$2:$AC$150,6,FALSE()) -> 1.0025 | D45: =B45*C45 -> 321.9228 | E45: =SUMIFS('Price Data'!$Q$2:$Q$150,'Price Data'!$L$2:$L$150,A45) -> 15.04 | F45: =(D45-D44)/D44 -> -0.085932706 | G45: =(E45-E44)/E44 -> -0.16860144
A46: =EDATE(A45,1) -> 44805 | B46: =VLOOKUP(A46,'Price Data'!$A$2:$F$150,6,FALSE()) -> 308.96 | C46: =VLOOKUP(A46,'Price Data'!$X$2:$AC$150,6,FALSE()) -> 0.983 | D46: =B46*C46 -> 303.70768 | E46: =SUMIFS('Price Data'!$Q$2:$Q$150,'Price Data'!$L$2:$L$150,A46) -> 12.1 | F46: =(D46-D45)/D45 -> -0.056582261 | G46: =(E46-E45)/E45 -> -0.19547872
A47: =EDATE(A46,1) -> 44835 | B47: =VLOOKUP(A47,'Price Data'!$A$2:$F$150,6,FALSE()) -> 297.59 | C47: =VLOOKUP(A47,'Price Data'!$X$2:$AC$150,6,FALSE()) -> 0.9955 | D47: =B47*C47 -> 296.25085 | E47: =SUMIFS('Price Data'!$Q$2:$Q$150,'Price Data'!$L$2:$L$150,A47) -> 13.45 | F47: =(D47-D46)/D46 -> -0.024552672 | G47: =(E47-E46)/E46 -> 0.11157025
...
